output.txt
Id: 10267 Type: Buy Price: 0.034116 Quantity: 265
Id: 2589 Type: Buy Price: 0.214133 Quantity: 323
Id: 15698 Type: Buy Price: 0.229404 Quantity: 612
Id: 30292 Type: Buy Price: 0.297151 Quantity: 129
Id: 31337 Type: Buy Price: 0.344193 Quantity: 124
Id: 14165 Type: Buy Price: 0.352923 Quantity: 728
Id: 22827 Type: Buy Price: 0.36882 Quantity: 456
Id: 16329 Type: Buy Price: 0.50977 Quantity: 942
Id: 14490 Type: Buy Price: 0.66549 Quantity: 123
Id: 17836 Type: Buy Price: 0.734366 Quantity: 650
Id: 31210 Type: Buy Price: 0.761069 Quantity: 399
Id: 11416 Type: Buy Price: 0.804975 Quantity: 70
Id: 3953 Type: Buy Price: 0.889593 Quantity: 861
Id: 20982 Type: Buy Price: 0.902441 Quantity: 264
Id: 16890 Type: Buy Price: 0.920789 Quantity: 933
Id: 4816 Type: Buy Price: 0.95658 Quantity: 938
Id: 30739 Type: Buy Price: 1.03155 Quantity: 325
Id: 2896 Type: Buy Price: 1.07144 Quantity: 692
Id: 8522 Type: Buy Price: 1.17854 Quantity: 650
Id: 52 Type: Buy Price: 1.31616 Quantity: 293
Id: 34944 Type: Buy Price: 1.35428 Quantity: 449
Id: 19445 Type: Buy Price: 1.48121 Quantity: 227
Id: 18989 Type: Buy Price: 1.48243 Quantity: 889
Id: 22869 Type: Buy Price: 1.49002 Quantity: 654
Id: 7062 Type: Buy Price: 1.51633 Quantity: 478
Id: 431 Type: Buy Price: 1.57128 Quantity: 586
Id: 38272 Type: Buy Price: 1.58246 Quantity: 229
Id: 7561 Type: Buy Price: 1.60577 Quantity: 878
Id: 10807 Type: Buy Price: 1.61191 Quantity: 868
Id: 29293 Type: Buy Price: 1.7054 Quantity: 840
Id: 24619 Type: Buy Price: 1.73122 Quantity: 140
Id: 29996 Type: Buy Price: 1.78585 Quantity: 720
Id: 31208 Type: Buy Price: 1.92682 Quantity: 404
Id: 34048 Type: Buy Price: 1.94983 Quantity: 588
Id: 33236 Type: Buy Price: 2.00216 Quantity: 565
Id: 32571 Type: Buy Price: 2.00427 Quantity: 130
Id: 20327 Type: Buy Price: 2.00944 Quantity: 73
Id: 13057 Type: Buy Price: 2.06932 Quantity: 101
Id: 21342 Type: Buy Price: 2.17634 Quantity: 662
Id: 31559 Type: Buy Price: 2.20029 Quantity: 804
Id: 30512 Type: Buy Price: 2.2703 Quantity: 880
Id: 27562 Type: Buy Price: 2.32514 Quantity: 162
Id: 26901 Type: Buy Price: 2.33785 Quantity: 944
Id: 10406 Type: Buy Price: 2.36766 Quantity: 34
Id: 12893 Type: Buy Price: 2.46149 Quantity: 131
Id: 20200 Type: Buy Price: 2.50734 Quantity: 62
Id: 16771 Type: Buy Price: 2.56657 Quantity: 433
Id: 28027 Type: Buy Price: 2.68939 Quantity: 415
Id: 31477 Type: Buy Price: 2.73476 Quantity: 147
Id: 5472 Type: Buy Price: 2.75485 Quantity: 532
Id: 6531 Type: Buy Price: 2.79102 Quantity: 537
Id: 4076 Type: Buy Price: 2.79161 Quantity: 153
Id: 17270 Type: Buy Price: 2.83075 Quantity: 58
Id: 19497 Type: Buy Price: 2.84786 Quantity: 839
Id: 8309 Type: Buy Price: 2.86885 Quantity: 630
Id: 10168 Type: Buy Price: 2.90807 Quantity: 411
Id: 8389 Type: Buy Price: 2.92061 Quantity: 805
Id: 24244 Type: Buy Price: 3.08727 Quantity: 471
Id: 16571 Type: Buy Price: 3.10723 Quantity: 260
Id: 7484 Type: Buy Price: 3.131 Quantity: 500
Id: 34519 Type: Buy Price: 3.24834 Quantity: 152
Id: 32281 Type: Buy Price: 3.32373 Quantity: 942
Id: 13108 Type: Buy Price: 3.59346 Quantity: 92
Id: 25951 Type: Buy Price: 3.62492 Quantity: 263
Id: 23557 Type: Buy Price: 3.67852 Quantity: 723
Id: 15807 Type: Buy Price: 3.68103 Quantity: 762
Id: 11280 Type: Buy Price: 3.72743 Quantity: 9
Id: 7409 Type: Buy Price: 3.74928 Quantity: 291
Id: 30359 Type: Buy Price: 3.76946 Quantity: 280
Id: 31413 Type: Buy Price: 3.80143 Quantity: 455
Id: 5007 Type: Buy Price: 3.85328 Quantity: 69
Id: 31890 Type: Buy Price: 3.87757 Quantity: 116
Id: 10293 Type: Buy Price: 3.89124 Quantity: 260
Id: 34783 Type: Buy Price: 3.95673 Quantity: 447
Id: 26684 Type: Buy Price: 3.97833 Quantity: 815
Id: 36888 Type: Buy Price: 3.98448 Quantity: 841
Id: 18073 Type: Buy Price: 3.98516 Quantity: 812
Id: 3025 Type: Buy Price: 4.09363 Quantity: 670
Id: 9422 Type: Buy Price: 4.13362 Quantity: 295
Id: 16259 Type: Buy Price: 4.20682 Quantity: 557
Id: 21020 Type: Buy Price: 4.25705 Quantity: 946
Id: 14264 Type: Buy Price: 4.30462 Quantity: 14
Id: 34759 Type: Buy Price: 4.3417 Quantity: 152
Id: 21546 Type: Buy Price: 4.35853 Quantity: 76
Id: 13083 Type: Buy Price: 4.37065 Quantity: 747
Id: 30281 Type: Buy Price: 4.43063 Quantity: 938
Id: 34958 Type: Buy Price: 4.50308 Quantity: 921
Id: 15672 Type: Buy Price: 4.52757 Quantity: 479
Id: 15385 Type: Buy Price: 4.61452 Quantity: 961
Id: 15939 Type: Buy Price: 4.71033 Quantity: 513
Id: 20960 Type: Buy Price: 4.80911 Quantity: 902
Id: 35035 Type: Buy Price: 5.01816 Quantity: 785
Id: 26003 Type: Buy Price: 5.08286 Quantity: 479
Id: 15403 Type: Buy Price: 5.19639 Quantity: 808
Id: 26460 Type: Buy Price: 5.22777 Quantity: 115
Id: 27592 Type: Buy Price: 5.23277 Quantity: 171
Id: 26831 Type: Buy Price: 5.35474 Quantity: 556
Id: 26801 Type: Buy Price: 5.35663 Quantity: 570
Id: 39097 Type: Buy Price: 5.35958 Quantity: 283
Id: 5399 Type: Buy Price: 5.58875 Quantity: 455
Id: 10201 Type: Buy Price: 5.59097 Quantity: 346
Id: 20545 Type: Buy Price: 5.5964 Quantity: 352
Id: 458 Type: Buy Price: 5.6824 Quantity: 283
Id: 15571 Type: Buy Price: 5.69958 Quantity: 750
Id: 28301 Type: Buy Price: 5.75052 Quantity: 839
Id: 27841 Type: Buy Price: 5.82818 Quantity: 36
Id: 10394 Type: Buy Price: 5.87462 Quantity: 278
Id: 16150 Type: Buy Price: 6.00318 Quantity: 423
Id: 18157 Type: Buy Price: 6.05036 Quantity: 137
Id: 10618 Type: Buy Price: 6.05044 Quantity: 410
Id: 14929 Type: Buy Price: 6.08362 Quantity: 66
Id: 15009 Type: Buy Price: 6.11791 Quantity: 504
Id: 28609 Type: Buy Price: 6.14161 Quantity: 950
Id: 25205 Type: Buy Price: 6.16829 Quantity: 153
Id: 23041 Type: Buy Price: 6.23987 Quantity: 830
Id: 12200 Type: Buy Price: 6.33188 Quantity: 622
Id: 1536 Type: Buy Price: 6.34277 Quantity: 596
Id: 13821 Type: Buy Price: 6.40006 Quantity: 356
Id: 37485 Type: Buy Price: 6.50264 Quantity: 630
Id: 34307 Type: Buy Price: 6.55639 Quantity: 482
Id: 38078 Type: Buy Price: 6.61916 Quantity: 256
Id: 23728 Type: Buy Price: 6.73249 Quantity: 65
Id: 37398 Type: Buy Price: 6.75535 Quantity: 169
Id: 28045 Type: Buy Price: 6.77512 Quantity: 469
Id: 19447 Type: Buy Price: 6.78767 Quantity: 806
Id: 30569 Type: Buy Price: 6.88956 Quantity: 382
Id: 16411 Type: Buy Price: 6.90819 Quantity: 368
Id: 35874 Type: Buy Price: 6.98514 Quantity: 323
Id: 5969 Type: Buy Price: 7.00323 Quantity: 532
Id: 24976 Type: Buy Price: 7.09875 Quantity: 566
Id: 26267 Type: Buy Price: 7.12889 Quantity: 362
Id: 37018 Type: Buy Price: 7.19679 Quantity: 290
Id: 19577 Type: Buy Price: 7.21118 Quantity: 750
Id: 29185 Type: Buy Price: 7.21188 Quantity: 240
Id: 26115 Type: Buy Price: 7.27065 Quantity: 832
Id: 32130 Type: Buy Price: 7.30114 Quantity: 557
Id: 14266 Type: Buy Price: 7.30655 Quantity: 195
Id: 35518 Type: Buy Price: 7.3071 Quantity: 39
Id: 27022 Type: Buy Price: 7.43769 Quantity: 681
Id: 21737 Type: Buy Price: 7.4818 Quantity: 46
Id: 18243 Type: Buy Price: 7.54038 Quantity: 501
Id: 272 Type: Buy Price: 7.56967 Quantity: 266
Id: 37094 Type: Buy Price: 7.57809 Quantity: 517
Id: 21769 Type: Buy Price: 7.61445 Quantity: 413
Id: 23289 Type: Buy Price: 7.62916 Quantity: 54
Id: 12641 Type: Buy Price: 7.77621 Quantity: 679
Id: 22112 Type: Buy Price: 7.79911 Quantity: 16
Id: 19803 Type: Buy Price: 7.80392 Quantity: 544
Id: 35594 Type: Buy Price: 7.80397 Quantity: 183
Id: 38060 Type: Buy Price: 7.84316 Quantity: 611
Id: 8868 Type: Buy Price: 7.8995 Quantity: 507
Id: 6216 Type: Buy Price: 7.96286 Quantity: 416
Id: 9036 Type: Buy Price: 8.03295 Quantity: 29
Id: 19094 Type: Buy Price: 8.08854 Quantity: 456
Id: 38393 Type: Buy Price: 8.15342 Quantity: 126
Id: 27011 Type: Buy Price: 8.1688 Quantity: 724
Id: 7749 Type: Buy Price: 8.18172 Quantity: 253
Id: 26967 Type: Buy Price: 8.19018 Quantity: 300
Id: 22467 Type: Buy Price: 8.39469 Quantity: 452
Id: 2802 Type: Buy Price: 8.4657 Quantity: 834
Id: 10648 Type: Buy Price: 8.50539 Quantity: 370
Id: 14738 Type: Buy Price: 8.5336 Quantity: 112
Id: 9803 Type: Buy Price: 8.57157 Quantity: 208
Id: 33374 Type: Buy Price: 8.64228 Quantity: 666
Id: 32503 Type: Buy Price: 8.7235 Quantity: 521
